<?xml version="1.0" encoding="utf-8"?>
<!-- =================================================================================== -->
<!-- |    This document was autogenerated by xacro from abb_with_measurement_tool.xacro | -->
<!-- |    EDITING THIS FILE BY HAND IS NOT RECOMMENDED                                 | -->
<!-- =================================================================================== -->
<robot name="abb_irb6640_with_camera_gripper">
  <material name="aluminum">
    <color rgba="0.5 0.5 0.5 1"/>
  </material>
  <material name="plastic">
    <color rgba="0.1 0.1 0.1 1"/>
  </material>
  <!-- link list -->
  <link name="base_link">
    <collision name="collision">
      <geometry>
        <mesh filename="package://abb_irb6640_support/meshes/irb6640_185_280/collision/base_link.stl"/>
      </geometry>
    </collision>
    <visual name="visual">
      <geometry>
        <mesh filename="package://abb_irb6640_support/meshes/irb6640_185_280/visual/base_link.dae"/>
      </geometry>
      <material name="yellow">
        <color rgba="1 1 0 1"/>
      </material>
    </visual>
  </link>
  <link name="link_1">
    <collision name="collision">
      <geometry>
        <mesh filename="package://abb_irb6640_support/meshes/irb6640_185_280/collision/link_1.stl"/>
      </geometry>
    </collision>
    <visual name="visual">
      <geometry>
        <mesh filename="package://abb_irb6640_support/meshes/irb6640_185_280/visual/link_1.dae"/>
      </geometry>
      <material name="yellow"/>
    </visual>
  </link>
  <link name="link_2">
    <collision name="collision">
      <geometry>
        <mesh filename="package://abb_irb6640_support/meshes/irb6640_185_280/collision/link_2.stl"/>
      </geometry>
    </collision>
    <visual name="visual">
      <geometry>
        <mesh filename="package://abb_irb6640_support/meshes/irb6640_185_280/visual/link_2.dae"/>
      </geometry>
      <material name="yellow"/>
    </visual>
  </link>
  <link name="link_3">
    <collision name="collision">
      <geometry>
        <mesh filename="package://abb_irb6640_support/meshes/irb6640_185_280/collision/link_3.stl"/>
      </geometry>
    </collision>
    <visual name="visual">
      <geometry>
        <mesh filename="package://abb_irb6640_support/meshes/irb6640_185_280/visual/link_3.dae"/>
      </geometry>
      <material name="yellow"/>
    </visual>
  </link>
  <link name="link_4">
    <collision name="collision">
      <geometry>
        <mesh filename="package://abb_irb6640_support/meshes/irb6640_185_280/collision/link_4.stl"/>
      </geometry>
    </collision>
    <visual name="visual">
      <geometry>
        <mesh filename="package://abb_irb6640_support/meshes/irb6640_185_280/visual/link_4.dae"/>
      </geometry>
      <material name="yellow"/>
    </visual>
  </link>
  <link name="link_5">
    <collision name="collision">
      <geometry>
        <mesh filename="package://abb_irb6640_support/meshes/irb6640_185_280/collision/link_5.stl"/>
      </geometry>
    </collision>
    <visual name="visual">
      <geometry>
        <mesh filename="package://abb_irb6640_support/meshes/irb6640_185_280/visual/link_5.dae"/>
      </geometry>
      <material name="yellow"/>
    </visual>
  </link>
  <link name="link_6">
    <collision name="collision">
      <geometry>
        <mesh filename="package://abb_irb6640_support/meshes/irb6640_185_280/collision/link_6.stl"/>
      </geometry>
    </collision>
    <visual name="visual">
      <geometry>
        <mesh filename="package://abb_irb6640_support/meshes/irb6640_185_280/visual/link_6.dae"/>
      </geometry>
      <material name="yellow"/>
    </visual>
  </link>
  <link name="tool0"/>
  <!--Cylinder and piston -->
  <link name="link_cylinder">
    <collision name="collision">
      <geometry>
        <mesh filename="package://abb_irb6640_support/meshes/irb6640_185_280/collision/cylinder_link.stl"/>
      </geometry>
    </collision>
    <visual name="visual">
      <geometry>
        <mesh filename="package://abb_irb6640_support/meshes/irb6640_185_280/visual/cylinder_link.dae"/>
      </geometry>
      <material name="yellow"/>
    </visual>
  </link>
  <link name="link_piston">
    <collision name="collision">
      <geometry>
        <mesh filename="package://abb_irb6640_support/meshes/irb6640_185_280/collision/piston_link.stl"/>
      </geometry>
    </collision>
    <visual name="visual">
      <geometry>
        <mesh filename="package://abb_irb6640_support/meshes/irb6640_185_280/visual/piston_link.dae"/>
      </geometry>
      <material name="yellow"/>
    </visual>
  </link>
  <!-- end of link list -->
  <!-- joint list -->
  <joint name="joint_1" type="revolute">
    <origin rpy="0 0 0" xyz="0 0 0.780"/>
    <axis xyz="0 0 1"/>
    <parent link="base_link"/>
    <child link="link_1"/>
    <limit effort="0" lower="-2.967" upper="2.967" velocity="1.7453"/>
  </joint>
  <joint name="joint_2" type="revolute">
    <origin rpy="0 0 0" xyz="0.320 0 0"/>
    <axis xyz="0 1 0"/>
    <parent link="link_1"/>
    <child link="link_2"/>
    <limit effort="0" lower="-1.134" upper="1.4855" velocity="1.5707"/>
  </joint>
  <joint name="joint_3" type="revolute">
    <origin rpy="0 0 0" xyz="0 0 1.075"/>
    <axis xyz="0 1 0"/>
    <parent link="link_2"/>
    <child link="link_3"/>
    <limit effort="0" lower="-3.142" upper="1.222" velocity="1.5707"/>
  </joint>
  <joint name="joint_4" type="revolute">
    <origin rpy="0 0 0" xyz="0 0 0.2"/>
    <axis xyz="1 0 0"/>
    <parent link="link_3"/>
    <child link="link_4"/>
    <limit effort="0" lower="-5.236" upper="5.236" velocity="2.9671"/>
  </joint>
  <joint name="joint_5" type="revolute">
    <origin rpy="0 0 0" xyz="1.392 0 0 "/>
    <axis xyz="0 1 0"/>
    <parent link="link_4"/>
    <child link="link_5"/>
    <limit effort="0" lower="-2.094" upper="2.094" velocity="2.4435"/>
  </joint>
  <joint name="joint_6" type="revolute">
    <origin rpy="0 0 0" xyz="0.2 0 0 "/>
    <axis xyz="1 0 0"/>
    <parent link="link_5"/>
    <child link="link_6"/>
    <limit effort="0" lower="-6.283" upper="6.283" velocity="3.3161"/>
  </joint>
  <joint name="joint_6-tool0" type="fixed">
    <parent link="link_6"/>
    <child link="tool0"/>
    <origin rpy="0 1.57079632679 0" xyz="0 0 0"/>
  </joint>
  <joint name="joint_cylinder" type="continuous">
    <origin rpy="0 0 0" xyz="-0.3647 0 -0.1455"/>
    <axis xyz="0 1 0"/>
    <parent link="link_1"/>
    <child link="link_cylinder"/>
    <mimic joint="joint_2" multiplier="-0.25"/>
  </joint>
  <joint name="joint_piston" type="continuous">
    <origin rpy="0 0 0" xyz="-0.22 0 -0.0672"/>
    <axis xyz="0 1 0"/>
    <parent link="link_2"/>
    <child link="link_piston"/>
    <mimic joint="joint_2" multiplier="-1.25"/>
  </joint>
  <!-- end of joint list -->
  <!-- ROS base_link to ABB World Coordinates transform -->
  <link name="base"/>
  <joint name="base_link-base" type="fixed">
    <origin rpy="0 0 0" xyz="0 0 0"/>
    <parent link="base_link"/>
    <child link="base"/>
  </joint>
  <!-- Create a fixed joint with a parameterized name. -->
  <joint name="measurement_tool_joint" type="fixed">
    <!-- The parent link must be read from the robot model it is attached to. -->
    <parent link="tool0"/>
    <child link="measurement_tool"/>
    <!-- The tool is directly attached to the flange. -->
    <origin rpy="0 0 0" xyz="0 0 0"/>
  </joint>
  <link name="measurement_tool">
    <visual>
      <geometry>
        <!-- The path to the visual meshes in the package. -->
        <mesh filename="package://abb_with_gripper/meshes/visual/pg70.dae"/>
      </geometry>
    </visual>
    <collision>
      <geometry>
        <!-- The path to the visual meshes in the package. -->
        <mesh filename="package://abb_with_gripper/meshes/visual/pg70.dae"/>
      </geometry>
    </collision>
  </link>
  <!-- LEFT FINGER BASE -->
  <joint name="finger_left_joint" type="prismatic">
    <parent link="measurement_tool"/>
    <child link="finger_left_link"/>
    <limit effort="100" lower="-0.001" upper="0.04" velocity="2.0"/>
    <origin rpy="0 0 0" xyz="0 0 0.0789"/>
    <axis xyz="0 1 0"/>
  </joint>
  <link name="finger_left_link">
    <visual>
      <geometry>
        <box size="0.03 0.01 0.01"/>
      </geometry>
      <material name="black">
        <color rgba="0 0 0 1"/>
      </material>
    </visual>
    <collision>
      <geometry>
        <box size="0.03 0.01 0.01"/>
      </geometry>
      <material name="black"/>
    </collision>
  </link>
  <!-- LEFT FINGERTIP -->
  <joint name="fingertip_left_joint" type="fixed">
    <parent link="finger_left_link"/>
    <child link="fingertip_left_link"/>
    <origin rpy="0 0 0" xyz="0 0.01 0.045"/>
  </joint>
  <link name="fingertip_left_link">
    <visual>
      <geometry>
        <box size="0.03 0.01 0.1"/>
      </geometry>
      <material name="silver">
        <color rgba="0.8 0.8 0.8 1"/>
      </material>
    </visual>
    <collision>
      <geometry>
        <box size="0.03 0.01 0.1"/>
      </geometry>
      <material name="black"/>
    </collision>
  </link>
  <!-- RIGHT FINGER BASE -->
  <joint name="finger_right_joint" type="prismatic">
    <mimic joint="finger_left_joint" multiplier="1" offset="0"/>
    <parent link="measurement_tool"/>
    <child link="finger_right_link"/>
    <limit effort="100" lower="-0.001" upper="0.04" velocity="2.0"/>
    <origin rpy="-0 0 0" xyz="0 0 0.0789"/>
    <axis xyz="0 -1 0"/>
  </joint>
  <link name="finger_right_link">
    <visual>
      <geometry>
        <box size="0.03 0.01 0.01"/>
      </geometry>
      <material name="black"/>
    </visual>
    <collision>
      <geometry>
        <box size="0.03 0.01 0.01"/>
      </geometry>
      <material name="black"/>
    </collision>
  </link>
  <!-- RIGHT FINGERTIP -->
  <joint name="fingertip_right_joint" type="fixed">
    <parent link="finger_right_link"/>
    <child link="fingertip_right_link"/>
    <origin rpy="0 0 0" xyz="0 -0.01 0.045"/>
  </joint>
  <link name="fingertip_right_link">
    <visual>
      <geometry>
        <box size="0.03 0.01 0.1"/>
      </geometry>
      <material name="silver"/>
    </visual>
    <collision>
      <geometry>
        <box size="0.03 0.01 0.1"/>
      </geometry>
      <material name="black"/>
    </collision>
  </link>
  <!-- TCP frame -->
  <joint name="tcp_joint" type="fixed">
    <origin rpy="0 0 0" xyz="0 0 0.116"/>
    <parent link="measurement_tool"/>
    <child link="tcp"/>
  </joint>
  <link name="tcp"/>
  <!-- camera body, with origin at bottom screw mount -->
  <joint name="camera_joint" type="fixed">
    <origin rpy="0 -1.57079632679 0" xyz="-0.1 0 0"/>
    <parent link="measurement_tool"/>
    <child link="camera_bottom_screw_frame"/>
  </joint>
  <link name="camera_bottom_screw_frame"/>
  <joint name="camera_link_joint" type="fixed">
    <origin rpy="0 0 0" xyz="0.0106 0.0175 0.0125"/>
    <parent link="camera_bottom_screw_frame"/>
    <child link="camera_link"/>
  </joint>
  <link name="camera_link">
    <visual>
      <!-- the mesh origin is at front plate in between the two infrared camera axes -->
      <origin rpy="1.57079632679 0 1.57079632679" xyz="0.0043 -0.0175 0"/>
      <geometry>
        <!-- ADDED SCALE MANUALLY-->
        <mesh filename="package://realsense2_description/meshes/d435.dae" scale="1.5 1.5 1.5"/>
      </geometry>
    </visual>
    <collision>
      <origin rpy="0 0 0" xyz="0 -0.0175 0"/>
      <geometry>
        <box size="0.02505 0.09 0.025"/>
      </geometry>
    </collision>
    <inertial>
      <!-- The following are not reliable values, and should not be used for modeling -->
      <mass value="0.072"/>
      <origin xyz="0 0 0"/>
      <inertia ixx="0.003881243" ixy="0.0" ixz="0.0" iyy="0.000498940" iyz="0.0" izz="0.003879257"/>
    </inertial>
  </link>
  <!-- camera depth joints and links -->
  <joint name="camera_depth_joint" type="fixed">
    <origin rpy="0 0 0" xyz="0 0 0"/>
    <parent link="camera_link"/>
    <child link="camera_depth_frame"/>
  </joint>
  <link name="camera_depth_frame"/>
  <joint name="camera_depth_optical_joint" type="fixed">
    <origin rpy="-1.57079632679 0 -1.57079632679" xyz="0 0 0"/>
    <parent link="camera_depth_frame"/>
    <child link="camera_depth_optical_frame"/>
  </joint>
  <link name="camera_depth_optical_frame"/>
  <!-- camera left IR joints and links -->
  <joint name="camera_infra1_joint" type="fixed">
    <origin rpy="0 0 0" xyz="0 0.0 0"/>
    <parent link="camera_link"/>
    <child link="camera_infra1_frame"/>
  </joint>
  <link name="camera_infra1_frame"/>
  <joint name="camera_infra1_optical_joint" type="fixed">
    <origin rpy="-1.57079632679 0 -1.57079632679" xyz="0 0 0"/>
    <parent link="camera_infra1_frame"/>
    <child link="camera_infra1_optical_frame"/>
  </joint>
  <link name="camera_infra1_optical_frame"/>
  <!-- camera right IR joints and links -->
  <joint name="camera_infra2_joint" type="fixed">
    <origin rpy="0 0 0" xyz="0 -0.05 0"/>
    <parent link="camera_link"/>
    <child link="camera_infra2_frame"/>
  </joint>
  <link name="camera_infra2_frame"/>
  <joint name="camera_infra2_optical_joint" type="fixed">
    <origin rpy="-1.57079632679 0 -1.57079632679" xyz="0 0 0"/>
    <parent link="camera_infra2_frame"/>
    <child link="camera_infra2_optical_frame"/>
  </joint>
  <link name="camera_infra2_optical_frame"/>
  <!-- camera color joints and links -->
  <joint name="camera_color_joint" type="fixed">
    <origin rpy="0 0 0" xyz="0 0.015 0"/>
    <parent link="camera_link"/>
    <child link="camera_color_frame"/>
  </joint>
  <link name="camera_color_frame"/>
  <joint name="camera_color_optical_joint" type="fixed">
    <origin rpy="-1.57079632679 0 -1.57079632679" xyz="0 0 0"/>
    <parent link="camera_color_frame"/>
    <child link="camera_color_optical_frame"/>
  </joint>
  <link name="camera_color_optical_frame"/>
  <!-- define the robot|s position and orientation in the world coordinate system -->
  <link name="world"/>
  <joint name="world_joint" type="fixed">
    <parent link="world"/>
    <child link="base_link"/>
    <!-- TODO: check base_link name of robot -->
    <origin rpy="0.0 0.0 0.0" xyz="0.0 0.0 0.0"/>
  </joint>
</robot>
